Workbook

Sheet Original
A1: Serviço | B1: Categoria | C1: Indicador | D1: Unid. | E1: Jan | F1: Fev | G1: Mar | H1: Abr | I1: Mai | J1: Jun | K1: Jul | L1: média jan-jul | M1: Ago | N1: Set | O1: Out | P1: Nov | Q1: Dez | R1: média ago-dez | S1: Total Ano
A2: Água | B2: RESIDENCIAL | C2: Economias faturadas residencial | D2: econ. | E2: 95895 | F2: 95891 | G2: 96078 | H2: 99572 | I2: 100007 | J2: 100215 | K2: 100452 | L2: =AVERAGE(E2:K2) | M2: 100678 | N2: 100793 | O2: 100908 | P2: 101073 | Q2: 101188 | R2: =AVERAGE(M2:Q2) | S2: =SUM(E2:K2)+SUM(M2:Q2)
A3: Água | B3: COMERCIAL | C3: Economias faturadas comercial | D3: econ. | E3: 7996 | F3: 8016 | G3: 7991 | H3: 8318 | I3: 8321 | J3: 8353 | K3: 8384 | L3: =AVERAGE(E3:K3) | M3: 8381 | N3: 8382 | O3: 8382 | P3: 8383 | Q3: 8383 | R3: =AVERAGE(M3:Q3) | S3: =SUM(E3:K3)+SUM(M3:Q3)
A4: Água | B4: INDUSTRIAL | C4: Economias faturadas industrial | D4: econ. | E4: 294 | F4: 297 | G4: 297 | H4: 300 | I4: 299 | J4: 300 | K4: 298 | L4: =AVERAGE(E4:K4) | M4: 297 | N4: 298 | O4: 299 | P4: 300 | Q4: 301 | R4: =AVERAGE(M4:Q4) | S4: =SUM(E4:K4)+SUM(M4:Q4)
A5: Água | B5: PÚBLICO | C5: Economias faturadas público | D5: econ. | E5: 565 | F5: 562 | G5: 561 | H5: 548 | I5: 550 | J5: 549 | K5: 551 | L5: =AVERAGE(E5:K5) | M5: 549 | N5: 550 | O5: 551 | P5: 552 | Q5: 553 | R5: =AVERAGE(M5:Q5) | S5: =SUM(E5:K5)+SUM(M5:Q5)
A6: Água | B6: RESIDENCIAL | C6: Volume medido residencial | D6: m³ | E6: 837548 | F6: 798686 | G6: 773464 | H6: 783539 | I6: 786598 | J6: 742685 | K6: 803979 | L6: =AVERAGE(E6:K6) | M6: 767346 | N6: 781691 | O6: 794828 | P6: 786483 | Q6: 821698 | R6: =AVERAGE(M6:Q6) | S6: =SUM(E6:K6)+SUM(M6:Q6)
A7: Água | B7: COMERCIAL | C7: Volume medido comercial | D7: m³ | E7: 70264 | F7: 76562 | G7: 71220 | H7: 76114 | I7: 75016 | J7: 72356 | K7: 76445 | L7: =AVERAGE(E7:K7) | M7: 82811 | N7: 85147 | O7: 83590 | P7: 83033 | Q7: 83555 | R7: =AVERAGE(M7:Q7) | S7: =SUM(E7:K7)+SUM(M7:Q7)
A8: Água | B8: INDUSTRIAL | C8: Volume medido industrial | D8: m³ | E8: 29662 | F8: 31339 | G8: 27807 | H8: 28276 | I8: 29469 | J8: 31113 | K8: 32674 | L8: =AVERAGE(E8:K8) | M8: 27120 | N8: 27720 | O8: 27910 | P8: 27941 | Q8: 27281 | R8: =AVERAGE(M8:Q8) | S8: =SUM(E8:K8)+SUM(M8:Q8)
A9: Água | B9: PÚBLICO | C9: Volume medido público | D9: m³ | E9: 30079 | F9: 33267 | G9: 35231 | H9: 36797 | I9: 35240 | J9: 38098 | K9: 34887 | L9: =AVERAGE(E9:K9) | M9: 33479 | N9: 38642 | O9: 38282 | P9: 35946 | Q9: 35047 | R9: =AVERAGE(M9:Q9) | S9: =SUM(E9:K9)+SUM(M9:Q9)
A10: Água | B10: RESIDENCIAL | C10: Volume faturado residencial | D10: m³ | E10: 1132341 | F10: 1110631 | G10: 1105063 | H10: 1142963 | I10: 1136589 | J10: 1130820 | K10: 1179363 | L10: =AVERAGE(E10:K10) | M10: 1150080 | N10: 1163167 | O10: 1172711 | P10: 1172280 | Q10: 1184420 | R10: =AVERAGE(M10:Q10) | S10: =SUM(E10:K10)+SUM(M10:Q10)
A11: Água | B11: COMERCIAL | C11: Volume faturado comercial | D11: m³ | E11: 103284 | F11: 107109 | G11: 103689 | H11: 109717 | I11: 108610 | J11: 109113 | K11: 110209 | L11: =AVERAGE(E11:K11) | M11: 126890 | N11: 128451 | O11: 127185 | P11: 126147 | Q11: 126277 | R11: =AVERAGE(M11:Q11) | S11: =SUM(E11:K11)+SUM(M11:Q11)
A12: Água | B12: INDUSTRIAL | C12: Volume faturado industrial | D12: m³ | E12: 31691 | F12: 33268 | G12: 30153 | H12: 30305 | I12: 31895 | J12: 33316 | K12: 32793 | L12: =AVERAGE(E12:K12) | M12: 28310 | N12: 28986 | O12: 29155 | P12: 29272 | Q12: 28629 | R12: =AVERAGE(M12:Q12) | S12: =SUM(E12:K12)+SUM(M12:Q12)
A13: Água | B13: PÚBLICO | C13: Volume faturado público | D13: m³ | E13: 31566 | F13: 33908 | G13: 36223 | H13: 38197 | I13: 35984 | J13: 38823 | K13: 35594 | L13: =AVERAGE(E13:K13) | M13: 34727 | N13: 39954 | O13: 39760 | P13: 37422 | Q13: 36393 | R13: =AVERAGE(M13:Q13) | S13: =SUM(E13:K13)+SUM(M13:Q13)
... A33: Esgoto | B33: PÚBLICO | C33: Valor público | D33: R$ | E33: 232962 | F33: 241592 | G33: 259283 | H33: 266502 | I33: 229841 | J33: 275896 | K33: 249601 | L33: =AVERAGE(E33:K33) | M33: 245006 | N33: 337899 | O33: 331532 | P33: 317584 | Q33: 303224 | R33: =AVERAGE(M33:Q33) | S33: =SUM(E33:K33)+SUM(M33:Q33)

Sheet Fatores
A1: Serviço | B1: Categoria | C1: MED/eco realizado (jan-jul) | D1: FAT/eco realizado (jan-jul) | E1: MED/eco projetado (ago-dez) | F1: FAT/eco projetado (ago-dez) | G1: Fator do MEDIDO (ago-dez) | H1: Fator do FATURADO (ago-dez) | I1: Alvo informado MED | J1: Alvo informado FAT | K1: Confere? (MED / FAT)
A2: Água | B2: RES | C2: =SUM(Original!E6:K6)/SUM(Original!E2:K2) | D2: =SUM(Original!E10:K10)/SUM(Original!E2:K2) | E2: =SUM(Original!M6:Q6)/SUM(Original!M2:Q2) | F2: =SUM(Original!M10:Q10)/SUM(Original!M2:Q2) | G2: 1 | H2: 1 | K2: sem alvo: fator 1 (não altera)
A3: Água | B3: COM | C3: =SUM(Original!E7:K7)/SUM(Original!E3:K3) | D3: =SUM(Original!E11:K11)/SUM(Original!E3:K3) | E3: =SUM(Original!M7:Q7)/SUM(Original!M3:Q3) | F3: =SUM(Original!M11:Q11)/SUM(Original!M3:Q3) | G3: =C3/E3 | H3: =D3/F3 | I3: 9.03 | J3: 13.1 | K3: =IF(AND(ABS(C3-I3)<0.006,ABS(D3-J3)<0.006),"sim","confira")
A4: Água | B4: IND | C4: =SUM(Original!E8:K8)/SUM(Original!E4:K4) | D4: =SUM(Original!E12:K12)/SUM(Original!E4:K4) | E4: =SUM(Original!M8:Q8)/SUM(Original!M4:Q4) | F4: =SUM(Original!M12:Q12)/SUM(Original!M4:Q4) | G4: =C4/E4 | H4: =D4/F4 | I4: 100.88 | J4: 107.16 | K4: =IF(AND(ABS(C4-I4)<0.006,ABS(D4-J4)<0.006),"sim","confira")
A5: Água | B5: PUB | C5: =SUM(Original!E9:K9)/SUM(Original!E5:K5) | D5: =SUM(Original!E13:K13)/SUM(Original!E5:K5) | E5: =SUM(Original!M9:Q9)/SUM(Original!M5:Q5) | F5: =SUM(Original!M13:Q13)/SUM(Original!M5:Q5) | G5: =C5/E5 | H5: =D5/F5 | I5: 62.69 | J5: 64.41 | K5: =IF(AND(ABS(C5-I5)<0.006,ABS(D5-J5)<0.006),"sim","confira")
A6: Esgoto | B6: RES | C6: =SUM(Original!E22:K22)/SUM(Original!E18:K18) | D6: =SUM(Original!E26:K26)/SUM(Original!E18:K18) | E6: =SUM(Original!M22:Q22)/SUM(Original!M18:Q18) | F6: =SUM(Original!M26:Q26)/SUM(Original!M18:Q18) | G6: 1 | H6: 1 | K6: sem alvo: fator 1 (não altera)
A7: Esgoto | B7: COM | C7: =SUM(Original!E23:K23)/SUM(Original!E19:K19) | D7: =SUM(Original!E27:K27)/SUM(Original!E19:K19) | E7: =SUM(Original!M23:Q23)/SUM(Original!M19:Q19) | F7: =SUM(Original!M27:Q27)/SUM(Original!M19:Q19) | G7: =C7/E7 | H7: =D7/F7 | I7: 9.62 | J7: 13.48 | K7: =IF(AND(ABS(C7-I7)<0.006,ABS(D7-J7)<0.006),"sim","confira")
A8: Esgoto | B8: IND | C8: =SUM(Original!E24:K24)/SUM(Original!E20:K20) | D8: =SUM(Original!E28:K28)/SUM(Original!E20:K20) | E8: =SUM(Original!M24:Q24)/SUM(Original!M20:Q20) | F8: =SUM(Original!M28:Q28)/SUM(Original!M20:Q20) | G8: =C8/E8 | H8: =D8/F8 | I8: 189.62 | J8: 173.45 | K8: =IF(AND(ABS(C8-I8)<0.006,ABS(D8-J8)<0.006),"sim","confira")
A9: Esgoto | B9: PUB | C9: =SUM(Original!E25:K25)/SUM(Original!E21:K21) | D9: =SUM(Original!E29:K29)/SUM(Original!E21:K21) | E9: =SUM(Original!M25:Q25)/SUM(Original!M21:Q21) | F9: =SUM(Original!M29:Q29)/SUM(Original!M21:Q21) | G9: =C9/E9 | H9: =D9/F9 | I9: 65.91 | J9: 66.1 | K9: =IF(AND(ABS(C9-I9)<0.006,ABS(D9-J9)<0.006),"sim","confira")
A11: Como ler: Fator = (indicador por economia realizado em Jan–Jul) ÷ (indicador por economia projetado em Ago–Dez). Multiplicar o volume e o valor de Ago–Dez por ele leva o ano fechado ao mesmo ritmo por economia do realizado. Economias e tarifas não mudam. Edite os fatores (amarelo) se quiser outro alvo.

Sheet Calibrado
A1: Serviço | B1: Categoria | C1: Indicador | D1: Unid. | E1: Jan | F1: Fev | G1: Mar | H1: Abr | I1: Mai | J1: Jun | K1: Jul | L1: média jan-jul | M1: Ago | N1: Set | O1: Out | P1: Nov | Q1: Dez | R1: média ago-dez | S1: Total Ano
A2: Água | B2: RESIDENCIAL | C2: Economias faturadas residencial | D2: econ. | E2: 95895 | F2: 95891 | G2: 96078 | H2: 99572 | I2: 100007 | J2: 100215 | K2: 100452 | L2: =AVERAGE(E2:K2) | M2: =Original!M2 | N2: =Original!N2 | O2: =Original!O2 | P2: =Original!P2 | Q2: =Original!Q2 | R2: =AVERAGE(M2:Q2) | S2: =SUM(E2:K2)+SUM(M2:Q2)
A3: Água | B3: COMERCIAL | C3: Economias faturadas comercial | D3: econ. | E3: 7996 | F3: 8016 | G3: 7991 | H3: 8318 | I3: 8321 | J3: 8353 | K3: 8384 | L3: =AVERAGE(E3:K3) | M3: =Original!M3 | N3: =Original!N3 | O3: =Original!O3 | P3: =Original!P3 | Q3: =Original!Q3 | R3: =AVERAGE(M3:Q3) | S3: =SUM(E3:K3)+SUM(M3:Q3)
A4: Água | B4: INDUSTRIAL | C4: Economias faturadas industrial | D4: econ. | E4: 294 | F4: 297 | G4: 297 | H4: 300 | I4: 299 | J4: 300 | K4: 298 | L4: =AVERAGE(E4:K4) | M4: =Original!M4 | N4: =Original!N4 | O4: =Original!O4 | P4: =Original!P4 | Q4: =Original!Q4 | R4: =AVERAGE(M4:Q4) | S4: =SUM(E4:K4)+SUM(M4:Q4)
A5: Água | B5: PÚBLICO | C5: Economias faturadas público | D5: econ. | E5: 565 | F5: 562 | G5: 561 | H5: 548 | I5: 550 | J5: 549 | K5: 551 | L5: =AVERAGE(E5:K5) | M5: =Original!M5 | N5: =Original!N5 | O5: =Original!O5 | P5: =Original!P5 | Q5: =Original!Q5 | R5: =AVERAGE(M5:Q5) | S5: =SUM(E5:K5)+SUM(M5:Q5)
A6: Água | B6: RESIDENCIAL | C6: Volume medido residencial | D6: m³ | E6: 837548 | F6: 798686 | G6: 773464 | H6: 783539 | I6: 786598 | J6: 742685 | K6: 803979 | L6: =AVERAGE(E6:K6) | M6: =Original!M6 | N6: =Original!N6 | O6: =Original!O6 | P6: =Original!P6 | Q6: =Original!Q6 | R6: =AVERAGE(M6:Q6) | S6: =SUM(E6:K6)+SUM(M6:Q6)
A7: Água | B7: COMERCIAL | C7: Volume medido comercial | D7: m³ | E7: 70264 | F7: 76562 | G7: 71220 | H7: 76114 | I7: 75016 | J7: 72356 | K7: 76445 | L7: =AVERAGE(E7:K7) | M7: =Original!M7*Fatores!$G$3 | N7: =Original!N7*Fatores!$G$3 | O7: =Original!O7*Fatores!$G$3 | P7: =Original!P7*Fatores!$G$3 | Q7: =Original!Q7*Fatores!$G$3 | R7: =AVERAGE(M7:Q7) | S7: =SUM(E7:K7)+SUM(M7:Q7)
A8: Água | B8: INDUSTRIAL | C8: Volume medido industrial | D8: m³ | E8: 29662 | F8: 31339 | G8: 27807 | H8: 28276 | I8: 29469 | J8: 31113 | K8: 32674 | L8: =AVERAGE(E8:K8) | M8: =Original!M8*Fatores!$G$4 | N8: =Original!N8*Fatores!$G$4 | O8: =Original!O8*Fatores!$G$4 | P8: =Original!P8*Fatores!$G$4 | Q8: =Original!Q8*Fatores!$G$4 | R8: =AVERAGE(M8:Q8) | S8: =SUM(E8:K8)+SUM(M8:Q8)
A9: Água | B9: PÚBLICO | C9: Volume medido público | D9: m³ | E9: 30079 | F9: 33267 | G9: 35231 | H9: 36797 | I9: 35240 | J9: 38098 | K9: 34887 | L9: =AVERAGE(E9:K9) | M9: =Original!M9*Fatores!$G$5 | N9: =Original!N9*Fatores!$G$5 | O9: =Original!O9*Fatores!$G$5 | P9: =Original!P9*Fatores!$G$5 | Q9: =Original!Q9*Fatores!$G$5 | R9: =AVERAGE(M9:Q9) | S9: =SUM(E9:K9)+SUM(M9:Q9)
A10: Água | B10: RESIDENCIAL | C10: Volume faturado residencial | D10: m³ | E10: 1132341 | F10: 1110631 | G10: 1105063 | H10: 1142963 | I10: 1136589 | J10: 1130820 | K10: 1179363 | L10: =AVERAGE(E10:K10) | M10: =Original!M10 | N10: =Original!N10 | O10: =Original!O10 | P10: =Original!P10 | Q10: =Original!Q10 | R10: =AVERAGE(M10:Q10) | S10: =SUM(E10:K10)+SUM(M10:Q10)
A11: Água | B11: COMERCIAL | C11: Volume faturado comercial | D11: m³ | E11: 103284 | F11: 107109 | G11: 103689 | H11: 109717 | I11: 108610 | J11: 109113 | K11: 110209 | L11: =AVERAGE(E11:K11) | M11: =Original!M11*Fatores!$H$3 | N11: =Original!N11*Fatores!$H$3 | O11: =Original!O11*Fatores!$H$3 | P11: =Original!P11*Fatores!$H$3 | Q11: =Original!Q11*Fatores!$H$3 | R11: =AVERAGE(M11:Q11) | S11: =SUM(E11:K11)+SUM(M11:Q11)
A12: Água | B12: INDUSTRIAL | C12: Volume faturado industrial | D12: m³ | E12: 31691 | F12: 33268 | G12: 30153 | H12: 30305 | I12: 31895 | J12: 33316 | K12: 32793 | L12: =AVERAGE(E12:K12) | M12: =Original!M12*Fatores!$H$4 | N12: =Original!N12*Fatores!$H$4 | O12: =Original!O12*Fatores!$H$4 | P12: =Original!P12*Fatores!$H$4 | Q12: =Original!Q12*Fatores!$H$4 | R12: =AVERAGE(M12:Q12) | S12: =SUM(E12:K12)+SUM(M12:Q12)
A13: Água | B13: PÚBLICO | C13: Volume faturado público | D13: m³ | E13: 31566 | F13: 33908 | G13: 36223 | H13: 38197 | I13: 35984 | J13: 38823 | K13: 35594 | L13: =AVERAGE(E13:K13) | M13: =Original!M13*Fatores!$H$5 | N13: =Original!N13*Fatores!$H$5 | O13: =Original!O13*Fatores!$H$5 | P13: =Original!P13*Fatores!$H$5 | Q13: =Original!Q13*Fatores!$H$5 | R13: =AVERAGE(M13:Q13) | S13: =SUM(E13:K13)+SUM(M13:Q13)
A14: Água | B14: RESIDENCIAL | C14: Valor residencial | D14: R$ | E14: 8922937 | F14: 8500290 | G14: 8374301 | H14: 8575972 | I14: 8221649 | J14: 8371315 | K14: 8556519 | L14: =AVERAGE(E14:K14) | M14: =Original!M14 | N14: =Original!N14 | O14: =Original!O14 | P14: =Original!P14 | Q14: =Original!Q14 | R14: =AVERAGE(M14:Q14) | S14: =SUM(E14:K14)+SUM(M14:Q14)
A15: Água | B15: COMERCIAL | C15: Valor comercial | D15: R$ | E15: 2945564 | F15: 3112837 | G15: 3013440 | H15: 3206712 | I15: 3003758 | J15: 3167512 | K15: 3193270 | L15: =AVERAGE(E15:K15) | M15: =Original!M15*Fatores!$H$3 | N15: =Original!N15*Fatores!$H$3 | O15: =Original!O15*Fatores!$H$3 | P15: =Original!P15*Fatores!$H$3 | Q15: =Original!Q15*Fatores!$H$3 | R15: =AVERAGE(M15:Q15) | S15: =SUM(E15:K15)+SUM(M15:Q15)
A16: Água | B16: INDUSTRIAL | C16: Valor industrial | D16: R$ | E16: 681289 | F16: 719839 | G16: 665568 | H16: 666440 | I16: 728050 | J16: 835970 | K16: 766499 | L16: =AVERAGE(E16:K16) | M16: =Original!M16*Fatores!$H$4 | N16: =Original!N16*Fatores!$H$4 | O16: =Original!O16*Fatores!$H$4 | P16: =Original!P16*Fatores!$H$4 | Q16: =Original!Q16*Fatores!$H$4 | R16: =AVERAGE(M16:Q16) | S16: =SUM(E16:K16)+SUM(M16:Q16)
A17: Água | B17: PÚBLICO | C17: Valor público | D17: R$ | E17: 340022 | F17: 347816 | G17: 371189 | H17: 390195 | I17: 343363 | J17: 413117 | K17: 360401 | L17: =AVERAGE(E17:K17) | M17: =Original!M17*Fatores!$H$5 | N17: =Original!N17*Fatores!$H$5 | O17: =Original!O17*Fatores!$H$5 | P17: =Original!P17*Fatores!$H$5 | Q17: =Original!Q17*Fatores!$H$5 | R17: =AVERAGE(M17:Q17) | S17: =SUM(E17:K17)+SUM(M17:Q17)
A18: Esgoto | B18: RESIDENCIAL | C18: Economias faturadas residencial | D18: econ. | E18: 68425 | F18: 68751 | G18: 68921 | H18: 69564 | I18: 71001 | J18: 71210 | K18: 71378 | L18: =AVERAGE(E18:K18) | M18: =Original!M18 | N18: =Original!N18 | O18: =Original!O18 | P18: =Original!P18 | Q18: =Original!Q18 | R18: =AVERAGE(M18:Q18) | S18: =SUM(E18:K18)+SUM(M18:Q18)
A19: Esgoto | B19: COMERCIAL | C19: Economias faturadas comercial | D19: econ. | E19: 7094 | F19: 7110 | G19: 7078 | H19: 7145 | I19: 7119 | J19: 7271 | K19: 7342 | L19: =AVERAGE(E19:K19) | M19: =Original!M19 | N19: =Original!N19 | O19: =Original!O19 | P19: =Original!P19 | Q19: =Original!Q19 | R19: =AVERAGE(M19:Q19) | S19: =SUM(E19:K19)+SUM(M19:Q19)
A20: Esgoto | B20: INDUSTRIAL | C20: Economias faturadas industrial | D20: econ. | E20: 140 | F20: 142 | G20: 141 | H20: 143 | I20: 143 | J20: 148 | K20: 151 | L20: =AVERAGE(E20:K20) | M20: =Original!M20 | N20: =Original!N20 | O20: =Original!O20 | P20: =Original!P20 | Q20: =Original!Q20 | R20: =AVERAGE(M20:Q20) | S20: =SUM(E20:K20)+SUM(M20:Q20)
A21: Esgoto | B21: PÚBLICO | C21: Economias faturadas público | D21: econ. | E21: 458 | F21: 457 | G21: 457 | H21: 444 | I21: 457 | J21: 448 | K21: 448 | L21: =AVERAGE(E21:K21) | M21: =Original!M21 | N21: =Original!N21 | O21: =Original!O21 | P21: =Original!P21 | Q21: =Original!Q21 | R21: =AVERAGE(M21:Q21) | S21: =SUM(E21:K21)+SUM(M21:Q21)
A22: Esgoto | B22: RESIDENCIAL | C22: Volume medido residencial | D22: m³ | E22: 596223 | F22: 577663 | G22: 564190 | H22: 580708 | I22: 572931 | J22: 556414 | K22: 606855 | L22: =AVERAGE(E22:K22) | M22: =Original!M22 | N22: =Original!N22 | O22: =Original!O22 | P22: =Original!P22 | Q22: =Original!Q22 | R22: =AVERAGE(M22:Q22) | S22: =SUM(E22:K22)+SUM(M22:Q22)
A23: Esgoto | B23: COMERCIAL | C23: Volume medido comercial | D23: m³ | E23: 64154 | F23: 69721 | G23: 65636 | H23: 71160 | I23: 69546 | J23: 69433 | K23: 72753 | L23: =AVERAGE(E23:K23) | M23: =Original!M23*Fatores!$G$7 | N23: =Original!N23*Fatores!$G$7 | O23: =Original!O23*Fatores!$G$7 | P23: =Original!P23*Fatores!$G$7 | Q23: =Original!Q23*Fatores!$G$7 | R23: =AVERAGE(M23:Q23) | S23: =SUM(E23:K23)+SUM(M23:Q23)
A24: Esgoto | B24: INDUSTRIAL | C24: Volume medido industrial | D24: m³ | E24: 26997 | F24: 30518 | G24: 26359 | H24: 26660 | I24: 25592 | J24: 26088 | K24: 28926 | L24: =AVERAGE(E24:K24) | M24: =Original!M24*Fatores!$G$8 | N24: =Original!N24*Fatores!$G$8 | O24: =Original!O24*Fatores!$G$8 | P24: =Original!P24*Fatores!$G$8 | Q24: =Original!Q24*Fatores!$G$8 | R24: =AVERAGE(M24:Q24) | S24: =SUM(E24:K24)+SUM(M24:Q24)
A25: Esgoto | B25: PÚBLICO | C25: Volume medido público | D25: m³ | E25: 25645 | F25: 28265 | G25: 30440 | H25: 31268 | I25: 29697 | J25: 32613 | K25: 30946 | L25: =AVERAGE(E25:K25) | M25: =Original!M25*Fatores!$G$9 | N25: =Original!N25*Fatores!$G$9 | O25: =Original!O25*Fatores!$G$9 | P25: =Original!P25*Fatores!$G$9 | Q25: =Original!Q25*Fatores!$G$9 | R25: =AVERAGE(M25:Q25) | S25: =SUM(E25:K25)+SUM(M25:Q25)
A26: Esgoto | B26: RESIDENCIAL | C26: Volume faturado residencial | D26: m³ | E26: 813877 | F26: 802752 | G26: 802074 | H26: 808103 | I26: 818595 | J26: 816138 | K26: 864510 | L26: =AVERAGE(E26:K26) | M26: =Original!M26 | N26: =Original!N26 | O26: =Original!O26 | P26: =Original!P26 | Q26: =Original!Q26 | R26: =AVERAGE(M26:Q26) | S26: =SUM(E26:K26)+SUM(M26:Q26)
A27: Esgoto | B27: COMERCIAL | C27: Volume faturado comercial | D27: m³ | E27: 93335 | F27: 95710 | G27: 92595 | H27: 97036 | I27: 96403 | J27: 98500 | K27: 102510 | L27: =AVERAGE(E27:K27) | M27: =Original!M27*Fatores!$H$7 | N27: =Original!N27*Fatores!$H$7 | O27: =Original!O27*Fatores!$H$7 | P27: =Original!P27*Fatores!$H$7 | Q27: =Original!Q27*Fatores!$H$7 | R27: =AVERAGE(M27:Q27) | S27: =SUM(E27:K27)+SUM(M27:Q27)
A28: Esgoto | B28: INDUSTRIAL | C28: Volume faturado industrial | D28: m³ | E28: 25824 | F28: 26977 | G28: 24205 | H28: 24008 | I28: 24005 | J28: 23935 | K28: 25879 | L28: =AVERAGE(E28:K28) | M28: =Original!M28*Fatores!$H$8 | N28: =Original!N28*Fatores!$H$8 | O28: =Original!O28*Fatores!$H$8 | P28: =Original!P28*Fatores!$H$8 | Q28: =Original!Q28*Fatores!$H$8 | R28: =AVERAGE(M28:Q28) | S28: =SUM(E28:K28)+SUM(M28:Q28)
A29: Esgoto | B29: PÚBLICO | C29: Volume faturado público | D29: m³ | E29: 26513 | F29: 28533 | G29: 30481 | H29: 31569 | I29: 29651 | J29: 32658 | K29: 30074 | L29: =AVERAGE(E29:K29) | M29: =Original!M29*Fatores!$H$9 | N29: =Original!N29*Fatores!$H$9 | O29: =Original!O29*Fatores!$H$9 | P29: =Original!P29*Fatores!$H$9 | Q29: =Original!Q29*Fatores!$H$9 | R29: =AVERAGE(M29:Q29) | S29: =SUM(E29:K29)+SUM(M29:Q29)
A30: Esgoto | B30: RESIDENCIAL | C30: Valor residencial | D30: R$ | E30: 4826786 | F30: 4690777 | G30: 4675493 | H30: 4616837 | I30: 4543942 | J30: 4662181 | K30: 4712757 | L30: =AVERAGE(E30:K30) | M30: =Original!M30 | N30: =Original!N30 | O30: =Original!O30 | P30: =Original!P30 | Q30: =Original!Q30 | R30: =AVERAGE(M30:Q30) | S30: =SUM(E30:K30)+SUM(M30:Q30)
A31: Esgoto | B31: COMERCIAL | C31: Valor comercial | D31: R$ | E31: 2220425 | F31: 2307034 | G31: 2252978 | H31: 2371559 | I31: 2255442 | J31: 2437479 | K31: 2489572 | L31: =AVERAGE(E31:K31) | M31: =Original!M31*Fatores!$H$7 | N31: =Original!N31*Fatores!$H$7 | O31: =Original!O31*Fatores!$H$7 | P31: =Original!P31*Fatores!$H$7 | Q31: =Original!Q31*Fatores!$H$7 | R31: =AVERAGE(M31:Q31) | S31: =SUM(E31:K31)+SUM(M31:Q31)
A32: Esgoto | B32: INDUSTRIAL | C32: Valor industrial | D32: R$ | E32: 276840 | F32: 281658 | G32: 266082 | H32: 254346 | I32: 247702 | J32: 248871 | K32: 248796 | L32: =AVERAGE(E32:K32) | M32: =Original!M32*Fatores!$H$8 | N32: =Original!N32*Fatores!$H$8 | O32: =Original!O32*Fatores!$H$8 | P32: =Original!P32*Fatores!$H$8 | Q32: =Original!Q32*Fatores!$H$8 | R32: =AVERAGE(M32:Q32) | S32: =SUM(E32:K32)+SUM(M32:Q32)
A33: Esgoto | B33: PÚBLICO | C33: Valor público | D33: R$ | E33: 232962 | F33: 241592 | G33: 259283 | H33: 266502 | I33: 229841 | J33: 275896 | K33: 249601 | L33: =AVERAGE(E33:K33) | M33: =Original!M33*Fatores!$H$9 | N33: =Original!N33*Fatores!$H$9 | O33: =Original!O33*Fatores!$H$9 | P33: =Original!P33*Fatores!$H$9 | Q33: =Original!Q33*Fatores!$H$9 | R33: =AVERAGE(M33:Q33) | S33: =SUM(E33:K33)+SUM(M33:Q33)
A35: CONFERÊNCIA — por economia (ano fechado com Ago–Dez calibrado)
A36: Serviço | B36: Categoria | C36: Indicador | E36: MED/eco jan-jul | F36: FAT/eco jan-jul | G36: MED/eco ago-dez | H36: FAT/eco ago-dez | I36: MED/eco ANO | J36: FAT/eco ANO
A37: Água | B37: RES | C37: volume ÷ economias | E37: =SUM(E6:K6)/SUM(E2:K2) | F37: =SUM(E10:K10)/SUM(E2:K2) | G37: =SUM(M6:Q6)/SUM(M2:Q2) | H37: =SUM(M10:Q10)/SUM(M2:Q2) | I37: =(SUM(E6:K6)+SUM(M6:Q6))/(SUM(E2:K2)+SUM(M2:Q2)) | J37: =(SUM(E10:K10)+SUM(M10:Q10))/(SUM(E2:K2)+SUM(M2:Q2))
A38: Água | B38: COM | C38: volume ÷ economias | E38: =SUM(E7:K7)/SUM(E3:K3) | F38: =SUM(E11:K11)/SUM(E3:K3) | G38: =SUM(M7:Q7)/SUM(M3:Q3) | H38: =SUM(M11:Q11)/SUM(M3:Q3) | I38: =(SUM(E7:K7)+SUM(M7:Q7))/(SUM(E3:K3)+SUM(M3:Q3)) | J38: =(SUM(E11:K11)+SUM(M11:Q11))/(SUM(E3:K3)+SUM(M3:Q3))
A39: Água | B39: IND | C39: volume ÷ economias | E39: =SUM(E8:K8)/SUM(E4:K4) | F39: =SUM(E12:K12)/SUM(E4:K4) | G39: =SUM(M8:Q8)/SUM(M4:Q4) | H39: =SUM(M12:Q12)/SUM(M4:Q4) | I39: =(SUM(E8:K8)+SUM(M8:Q8))/(SUM(E4:K4)+SUM(M4:Q4)) | J39: =(SUM(E12:K12)+SUM(M12:Q12))/(SUM(E4:K4)+SUM(M4:Q4))
A40: Água | B40: PUB | C40: volume ÷ economias | E40: =SUM(E9:K9)/SUM(E5:K5) | F40: =SUM(E13:K13)/SUM(E5:K5) | G40: =SUM(M9:Q9)/SUM(M5:Q5) | H40: =SUM(M13:Q13)/SUM(M5:Q5) | I40: =(SUM(E9:K9)+SUM(M9:Q9))/(SUM(E5:K5)+SUM(M5:Q5)) | J40: =(SUM(E13:K13)+SUM(M13:Q13))/(SUM(E5:K5)+SUM(M5:Q5))
A41: Esgoto | B41: RES | C41: volume ÷ economias | E41: =SUM(E22:K22)/SUM(E18:K18) | F41: =SUM(E26:K26)/SUM(E18:K18) | G41: =SUM(M22:Q22)/SUM(M18:Q18) | H41: =SUM(M26:Q26)/SUM(M18:Q18) | I41: =(SUM(E22:K22)+SUM(M22:Q22))/(SUM(E18:K18)+SUM(M18:Q18)) | J41: =(SUM(E26:K26)+SUM(M26:Q26))/(SUM(E18:K18)+SUM(M18:Q18))
...
